Workbook

Sheet TAKIM
B2: BEYLERBEYİ 1911 AKADEMİ
E4: U19 | N4: 2025-2026
B18: KALECİ | E18: KALECİ | H18: SAĞBEK | K18: SAĞBEK | N18: STOPER | Q18: STOPER
B19: AD SOYAD | C19: ÖMÜR ÇİLESİZ | E19: AD SOYAD | F19: SİNAN SARGIN | H19: AD SOYAD | I19: EMİRHAN ÇELİK | K19: AD SOYAD | L19: YASİN ERDEM ÖZTÜRK | N19: AD SOYAD | O19: ULAÇ KANDAZ | Q19: AD SOYAD | R19: METEHAN COŞKUN
B20: DOĞUM TARİHİ | C20: 2008 | E20: DOĞUM TARİHİ | F20: 2008 | H20: DOĞUM TARİHİ | I20: 2009 | K20: DOĞUM TARİHİ | L20: 2008 | N20: DOĞUM TARİHİ | O20: 2007 | Q20: DOĞUM TARİHİ | R20: 2008
B21: BOY/KİLO | E21: BOY/KİLO | H21: BOY/KİLO | K21: BOY/KİLO | N21: BOY/KİLO | Q21: BOY/KİLO
B22: GELDİĞİ TAKIM | C22: ÜMRANİYESPOR | E22: GELDİĞİ TAKIM | F22: SULTANBEYLİ | H22: GELDİĞİ TAKIM | I22: BEYLERBEYİ 1911 | K22: GELDİĞİ TAKIM | N22: GELDİĞİ TAKIM | Q22: GELDİĞİ TAKIM
B23: ALDIĞI SÜRE (DK) | E23: ALDIĞI SÜRE (DK) | H23: ALDIĞI SÜRE (DK) | K23: ALDIĞI SÜRE (DK) | N23: ALDIĞI SÜRE (DK) | Q23: ALDIĞI SÜRE (DK)
B24: YEDİĞİ GOL SAYISI | E24: YEDİĞİ GOL SAYISI | H24: YEDİĞİ GOL SAYISI | K24: GOL SAYISI | N24: GOL SAYISI | Q24: GOL SAYISI
B25: ASİST SAYISI | E25: ASİST SAYISI | H25: ASİST SAYISI | K25: ASİST SAYISI | N25: ASİST SAYISI | Q25: ASİST SAYISI
B36: FORVET | E36: STOPER | H36: STOPER | K36: SOLBEK | N36: SOLBEK | Q36: ORTA SAHA
B37: AD SOYAD | C37: HALİT YILIDRIM | E37: AD SOYAD | H37: AD SOYAD | K37: AD SOYAD | L37: ARDA AYVALI | N37: AD SOYAD | O37: TÜRKER ÇEBİ | Q37: AD SOYAD | R37: KADİR GEDİK
B38: DOĞUM TARİHİ | C38: 2007 | E38: DOĞUM TARİHİ | H38: DOĞUM TARİHİ | K38: DOĞUM TARİHİ | L38: 2007 | N38: DOĞUM TARİHİ | O38: 2008 | Q38: DOĞUM TARİHİ | R38: 2007
B39: BOY/KİLO | E39: BOY/KİLO | H39: BOY/KİLO | K39: BOY/KİLO | N39: BOY/KİLO | Q39: BOY/KİLO
B40: GELDİĞİ TAKIM | E40: GELDİĞİ TAKIM | H40: GELDİĞİ TAKIM | K40: GELDİĞİ TAKIM | N40: GELDİĞİ TAKIM | Q40: GELDİĞİ TAKIM
B41: ALDIĞI SÜRE (DK) | E41: ALDIĞI SÜRE (DK) | H41: ALDIĞI SÜRE (DK) | K41: ALDIĞI SÜRE (DK) | N41: ALDIĞI SÜRE (DK) | Q41: ALDIĞI SÜRE (DK)
B42: GOL SAYISI | E42: GOL SAYISI | H42: GOL SAYISI | K42: GOL SAYISI | N42: GOL SAYISI | Q42: GOL SAYISI
B43: ASİST SAYISI | E43: ASİST SAYISI | H43: ASİST SAYISI | K43: ASİST SAYISI | N43: ASİST SAYISI | Q43: ASİST SAYISI
B69: ORTA SAHA | E69: ORTA SAHA | H69: ORTA SAHA | K69: ORTA SAHA | N69: ORTA SAHA | Q69: KANAT FORVET
B70: AD SOYAD | C70: UMUT BAK | E70: AD SOYAD | H70: AD SOYAD | I70: EGE BARIŞ DEMİR | K70: AD SOYAD | L70: ALPEREN VAROL | N70: AD SOYAD | Q70: AD SOYAD | R70: YİĞİT YAZICI
B71: DOĞUM TARİHİ | C71: 2007 | E71: DOĞUM TARİHİ | H71: DOĞUM TARİHİ | I71: 2007 | K71: DOĞUM TARİHİ | L71: 2009 | N71: DOĞUM TARİHİ | Q71: DOĞUM TARİHİ | R71: 2008
B72: BOY/KİLO | E72: BOY/KİLO | H72: BOY/KİLO | K72: BOY/KİLO | N72: BOY/KİLO | Q72: BOY/KİLO
B73: GELDİĞİ TAKIM | E73: GELDİĞİ TAKIM | H73: GELDİĞİ TAKIM | I73: YENİKÖY | K73: GELDİĞİ TAKIM | L73: BEYLERBEYİ 1911 | N73: GELDİĞİ TAKIM | Q73: GELDİĞİ TAKIM
B74: ALDIĞI SÜRE (DK) | E74: ALDIĞI SÜRE (DK) | H74: ALDIĞI SÜRE (DK) | K74: ALDIĞI SÜRE (DK) | N74: ALDIĞI SÜRE (DK) | Q74: ALDIĞI SÜRE (DK)
B75: GOL SAYISI | E75: GOL SAYISI | H75: GOL SAYISI | K75: GOL SAYISI | N75: GOL SAYISI | Q75: GOL SAYISI
B76: ASİST SAYISI | E76: ASİST SAYISI | H76: ASİST SAYISI | K76: ASİST SAYISI | N76: ASİST SAYISI | Q76: ASİST SAYISI
B88: KANAT FORVET | E88: KANAT FORVET | H88: KANAT FORVET | K88: KANAT FORVET | N88: SANTRAFOR | Q88: SANTRAFOR
B89: AD SOYAD | E89: AD SOYAD | H89: AD SOYAD | K89: AD SOYAD | L89: BERK DAVULCU | N89: AD SOYAD | O89: ALP DEĞİRMENCİ | Q89: AD SOYAD | R89: EYÜP SİLMEZ
B90: DOĞUM TARİHİ | E90: DOĞUM TARİHİ | H90: DOĞUM TARİHİ | K90: DOĞUM TARİHİ | L90: 2007 | N90: DOĞUM TARİHİ | O90: 2007 | Q90: DOĞUM TARİHİ | R90: 2008
B91: BOY/KİLO | E91: BOY/KİLO | H91: BOY/KİLO | K91: BOY/KİLO | N91: BOY/KİLO | Q91: BOY/KİLO
B92: GELDİĞİ TAKIM | E92: GELDİĞİ TAKIM | H92: GELDİĞİ TAKIM | K92: GELDİĞİ TAKIM | L92: ÜMRANİYESPOR | N92: GELDİĞİ TAKIM | Q92: GELDİĞİ TAKIM
B93: ALDIĞI SÜRE (DK) | E93: ALDIĞI SÜRE (DK) | H93: ALDIĞI SÜRE (DK) | K93: ALDIĞI SÜRE (DK) | N93: ALDIĞI SÜRE (DK) | Q93: ALDIĞI SÜRE (DK)
B94: GOL SAYISI | E94: GOL SAYISI | H94: GOL SAYISI | K94: GOL SAYISI | N94: GOL SAYISI | Q94: GOL SAYISI
B95: ASİST SAYISI | E95: ASİST SAYISI | H95: ASİST SAYISI | K95: ASİST SAYISI | N95: ASİST SAYISI | Q95: ASİST SAYISI

Sheet DAKIKA
B2: DAKİKA
B3: U-19 2025-2026 Sezonu
E4: HAZIRLIK MAÇI | L4: HAZIRLIK MAÇLARI | M4: 1. DEVRE | AF4: DEVRE ARASI | AG4: TOPLAM | AH4: 2.DEVRE
E5: 1 | F5: 2 | G5: 3 | H5: 4 | I5: 5 | J5: 6 | K5: T | M5: 1 | N5: 2 | O5: 3 | P5: 4 | Q5: 5 | R5: 6 | S5: 7 | T5: 8 | U5: 9 | V5: 10 | W5: 11 | X5: 12 | Y5: 13 | Z5: 14 | AA5: 15 | AH5: 16 | AI5: 17 | AJ5: 18 | AK5: 19 | AL5: 20 | AM5: 21 | AN5: 22 | AO5: 23 | AP5: 24 | AQ5: 25 | AR5: 26 | AS5: 27 | AT5: 28 | AU5: 29 | AV5: 30
E6: D | F6: E | G6: D | H6: E | I6: E | J6: D | M6: D | N6: E | O6: D | P6: E | Q6: D | R6: E | S6: D | T6: E | U6: D | V6: E | W6: D | X6: E | Y6: D | Z6: E | AA6: D | AH6: E | AI6: D | AJ6: E | AK6: D | AL6: E | AM6: D | AN6: E | AO6: D | AP6: E | AQ6: D | AR6: E | AS6: D | AT6: E | AU6: D | AV6: E
K7: TOPLAM | M7: SANCAKTEPE SPOR | N7: GÖLCÜKSPOR | O7: KESTEL ÇİLEK SPOR KULÜBÜ | P7: BULVARSPOR | Q7: KARTAL SPORTİF FAALİYETLERİ A.Ş. | R7: SULTANBEYLİ BELEDİYE SPOR | S7: DUDULLU | T7: İNKILAP FUTBOL SPOR KULÜBÜ | U7: GÜZİDE GEBZE SPOR KULÜBÜ | V7: PAŞABAHÇE | W7: KARACABEY BELEDİYE SPOR A.Ş. | X7: KULLAR 1975 SPOR | Y7: YALOVA FK 77 SPOR KULÜBÜ | Z7: MALTEPESPOR | AA7: BEYKOZ ANADOLU SPOR A.Ş. | AH7: SANCAKTEPE SPOR | AI7: GÖLCÜKSPOR | AJ7: KESTEL ÇİLEK SPOR KULÜBÜ | AK7: BULVARSPOR | AL7: KARTAL SPORTİF FAALİYETLERİ A.Ş. | AM7: SULTANBEYLİ BELEDİYE SPOR | AN7: DUDULLU | AO7: İNKILAP FUTBOL SPOR KULÜBÜ | AP7: GÜZİDE GEBZE SPOR KULÜBÜ | AQ7: PAŞABAHÇE | AR7: KARACABEY BELEDİYE SPOR A.Ş. | AS7: KULLAR 1975 SPOR | AT7: YALOVA FK 77 SPOR KULÜBÜ | AU7: MALTEPESPOR | AV7: BEYKOZ ANADOLU SPOR A.Ş. | BA7: SON
M8: 17 | N8: 24 | O8: 1 | P8: 8 | Q8: 15 | R8: 22 | S8: 29 | T8: 5 | U8: 12 | V8: 19 | W8: 26 | X8: 3 | Y8: 10 | Z8: 17 | AA8: 24 | AH8: 29 | AI8: 7 | AJ8: 14 | AK8: 21 | AL8: 28 | AM8: 4 | AN8: 11 | AO8: 18 | AP8: 25 | AQ8: 4 | AR8: 11 | AS8: 25 | AT8: 1 | AU8: 8 | AV8: 15
M9: EYLÜL | O9: EKİM | T9: KASIM | X9: ARALIK | AI9: OCAK | AM9: ŞUBAT | AQ9: MART | AT9: NİSAN
B10: 1 | C10: ÖMÜR ÇİLESİZ | K10: =SUM(E10:J10) -> 0 | AA10: SA | AG10: =SUM(M10:AF10) -> 0 | AH10: SA | AI10: SA | AJ10: 90 | AK10: 90 | AL10: 90 | AM10: SA | BB10: =SUM(M10:AF10,AH10:BA10) -> 270
B11: 2 | C11: SİNAN SARGIN | K11: =SUM(E11:J11) -> 0 | M11: SA | N11: 90 | O11: 90 | P11: 90 | Q11: SA | R11: 90 | S11: 90 | T11: 35 | U11: 90 | V11: 90 | W11: 90 | X11: 90 | Y11: 90 | Z11: 90 | AA11: 90 | AG11: =SUM(M11:AF11) -> 1115 | AH11: 90 | AI11: 90 | AJ11: S | AK11: SA | AL11: SA | AM11: 90 | BB11: =SUM(M11:AF11,AH11:BA11) -> 1385
B12: 3 | C12: EMİRHAN ÇELİK | K12: =SUM(E12:J12) -> 0 | M12: KY | N12: KY | O12: KY | P12: KY | Q12: KY | R12: KY | S12: 45 | T12: 90 | U12: 90 | V12: KY | W12: 45 | X12: 90 | Y12: 90 | Z12: 75 | AA12: 90 | AG12: =SUM(M12:AF12) -> 615 | AH12: 45 | AI12: 90 | AJ12: 90 | AK12: 90 | AL12: 90 | AM12: 90 | BB12: =SUM(M12:AF12,AH12:BA12) -> 1110
B13: 4 | C13: YASİN ERDEM ÖZTÜRK | K13: =SUM(E13:J13) -> 0 | M13: SA | N13: SA | O13: SA | P13: SA | Q13: 90 | R13: 45 | S13: S | T13: S | U13: S | V13: S | W13: S | X13: S | Y13: S | Z13: S | AA13: S | AG13: =SUM(M13:AF13) -> 135 | AH13: S | AI13: S | AJ13: S | AK13: S | AL13: S | AM13: S | AN13: S | AO13: S | AP13: S | AQ13: S | AR13: S | AS13: S | AT13: S | AU13: S | AV13: S | BB13: =SUM(M13:AF13,AH13:BA13) -> 135
B14: 5 | C14: YASİN ALBAYRAK | K14: =SUM(E14:J14) -> 0 | M14: 90 | N14: KY | O14: 90 | P14: 90 | Q14: SA | R14: SA | S14: 90 | T14: 90 | U14: 90 | V14: 90 | W14: 90 | X14: 50 | Y14: 90 | Z14: 90 | AA14: 90 | AG14: =SUM(M14:AF14) -> 1040 | AH14: 90 | AI14: 90 | AJ14: 90 | AK14: C | AL14: 90 | AM14: 90 | BB14: =SUM(M14:AF14,AH14:BA14) -> 1490
B15: 6 | C15: ULAÇ KANDAZ | K15: =SUM(E15:J15) -> 0 | M15: KY | N15: KY | O15: 80 | P15: 45 | Q15: 90 | R15: 78 | S15: SA | T15: SA | U15: SA | V15: 90 | W15: 90 | X15: 90 | Y15: 90 | Z15: 90 | AA15: 90 | AG15: =SUM(M15:AF15) -> 833 | AH15: 87 | AI15: 90 | AJ15: 90 | AK15: 90 | AL15: 90 | AM15: C | BB15: =SUM(M15:AF15,AH15:BA15) -> 1280
B16: 7 | C16: METEHAN COŞKUN | K16: =SUM(E16:J16) -> 0 | M16: KY | N16: KY | O16: 30 | P16: 90 | Q16: 90 | R16: 90 | S16: 90 | T16: 90 | U16: 90 | V16: SA | W16: 45 | X16: 90 | Y16: 90 | Z16: C | AA16: 90 | AG16: =SUM(M16:AF16) -> 885 | AH16: 90 | AI16: 90 | AJ16: 65 | AK16: 90 | AL16: 45 | AM16: 90 | BB16: =SUM(M16:AF16,AH16:BA16) -> 1355
B17: 8 | C17: UMUT EGEMEN KUTLU | K17: =SUM(E17:J17) -> 0 | M17: SA | N17: 90 | O17: KY | P17: KY | Q17: KY | R17: KY | S17: SA | T17: SA | U17: SA | V17: SA | W17: SA | X17: S | Y17: S | Z17: S | AA17: S | AG17: =SUM(M17:AF17) -> 90 | AH17: S | AI17: S | AJ17: S | AK17: S | AL17: S | AM17: S | AN17: S | AO17: S | AP17: S | AQ17: S | AR17: S | AS17: S | AT17: S | AU17: S | AV17: S | BB17: =SUM(M17:AF17,AH17:BA17) -> 90
B18: 9 | C18: MİRAÇ EMİR YILDIZ | K18: =SUM(E18:J18) -> 0 | M18: 90 | N18: 61 | O18: SA | P18: KY | Q18: SA | R18: 90 | S18: 45 | T18: 65 | U18: 90 | V18: SA | W18: 45 | X18: SA | Y18: SA | Z18: 5 | AA18: SA | AG18: =SUM(M18:AF18) -> 491 | AH18: 5 | AI18: SA | AJ18: 25 | AK18: 45 | AL18: KY | AM18: KY | AN18: KY | AO18: KY | AP18: KY | AQ18: KY | AR18: KY | AS18: KY | AT18: KY | AU18: KY | AV18: KY | BB18: =SUM(M18:AF18,AH18:BA18) -> 566
B19: 10 | C19: ARDA AYVALI | K19: =SUM(E19:J19) -> 0 | M19: 90 | N19: 90 | O19: 90 | P19: 90 | Q19: 81 | R19: 90 | S19: 45 | T19: 45 | U19: 90 | V19: 90 | W19: 90 | X19: 60 | Y19: 90 | Z19: 90 | AA19: 45 | AG19: =SUM(M19:AF19) -> 1176 | AH19: SA | AI19: SA | AJ19: 90 | AK19: 45 | AL19: SA | AM19: 35 | BB19: =SUM(M19:AF19,AH19:BA19) -> 1346
B20: 11 | C20: TÜRKER ÇEBİ | K20: =SUM(E20:J20) -> 0 | M20: 16 | N20: 61 | O20: 22 | P20: SA | Q20: 10 | R20: SA | S20: 90 | T20: 45 | U20: SA | V20: SA | W20: SA | X20: 30 | Y20: SA | Z20: SA | AA20: 45 | AG20: =SUM(M20:AF20) -> 319 | AH20: 45 | AI20: 90 | AJ20: SA | AK20: SA | AL20: 70 | AM20: SA | BB20: =SUM(M20:AF20,AH20:BA20) -> 524
B21: 12 | C21: EGE BARIŞ DEMİR | K21: =SUM(E21:J21) -> 0 | M21: 45 | N21: 90 | O21: 90 | P21: 45 | Q21: 70 | R21: 55 | S21: 90 | T21: 45 | U21: C | V21: 90 | W21: 90 | X21: 45 | Y21: 86 | Z21: 63 | AA21: 75 | AG21: =SUM(M21:AF21) -> 979 | AH21: 70 | AI21: 64 | AJ21: 90 | AK21: 90 | AL21: 90 | AM21: 90 | AN21: C | BB21: =SUM(M21:AF21,AH21:BA21) -> 1473
B22: 13 | C22: ARDA ÇORUK | K22: =SUM(E22:J22) -> 0 | AA22: SA | AG22: =SUM(M22:AF22) -> 0 | AH22: 90 | AI22: SA | AJ22: KY | AK22: 45 | AL22: 20 | AM22: 90 | BB22: =SUM(M22:AF22,AH22:BA22) -> 245
B23: 14 | C23: UMUT BAK | K23: =SUM(E23:J23) -> 0 | M23: 45 | N23: 84 | O23: 15 | P23: 35 | Q23: S | R23: S | S23: S | T23: S | U23: S | V23: S | W23: S | X23: S | Y23: S | Z23: SA | AA23: SA | AG23: =SUM(M23:AF23) -> 179 | AH23: 20 | AI23: SA | AJ23: SA | AK23: SA | AL23: SA | AM23: KY | BB23: =SUM(M23:AF23,AH23:BA23) -> 199
B24: 15 | C24: BERKAY ÜST | K24: =SUM(E24:J24) -> 0 | M24: 45 | N24: 45 | O24: 35 | P24: 45 | Q24: 90 | R24: 90 | S24: 82 | T24: 90 | U24: 70 | V24: 90 | W24: KY | X24: KY | Y24: KY | Z24: KY | AA24: KY | AG24: =SUM(M24:AF24) -> 682 | AH24: KY | AI24: KY | AJ24: KY | AK24: KY | AL24: KY | AM24: KY | AN24: KY | AO24: KY | AP24: KY | AQ24: KY | AR24: KY | AS24: KY | AT24: KY | AU24: KY | AV24: KY | BB24: =SUM(M24:AF24,AH24:BA24) -> 682
B25: 16 | C25: KADİR GEDİK | K25: =SUM(E25:J25) -> 0 | M25: 61 | N25: 45 | O25: 60 | P25: 45 | Q25: 65 | R25: 35 | S25: 75 | T25: KY | U25: 20 | V25: 16 | W25: 70 | X25: 90 | Y25: 62 | Z25: 80 | AA25: C | AG25: =SUM(M25:AF25) -> 724 | AH25: 55 | AI25: 45 | AJ25: 32 | AK25: C | AL25: 45 | AM25: 45 | BB25: =SUM(M25:AF25,AH25:BA25) -> 946
B26: 17 | C26: ALPEREN VAROL | K26: =SUM(E26:J26) -> 0 | M26: KY | N26: KY | O26: KY | P26: KY | Q26: KY | R26: 78 | S26: 59 | T26: 45 | U26: 30 | V26: KY | W26: 20 | X26: 45 | Y26: 25 | Z26: 90 | AA26: 25 | AG26: =SUM(M26:AF26) -> 417 | AH26: 35 | AI26: 25 | AJ26: SA | AK26: 63 | AL26: 45 | AM26: 45 | BB26: =SUM(M26:AF26,AH26:BA26) -> 630
B27: 18 | C27: YİĞİT YAZICI | K27: =SUM(E27:J27) -> 0 | M27: 90 | N27: 61 | O27: 45 | P27: 30 | Q27: 45 | R27: SA | S27: 8 | T27: SA | U27: 60 | V27: 12 | W27: 25 | X27: 10 | Y27: KY | Z27: 45 | AA27: 20 | AG27: =SUM(M27:AF27) -> 451 | AH27: 90 | AI27: KY | AJ27: 25 | AK27: 30 | AL27: 76 | AM27: 70 | BB27: =SUM(M27:AF27,AH27:BA27) -> 742
B28: 19 | C28: EMİR KAMA | K28: =SUM(E28:J28) -> 0 | M28: SA | N28: 17 | O28: 8 | P28: SA | Q28: 30 | R28: 45 | S28: SA | T28: SA | U28: SA | V28: 65 | W28: 45 | X28: SA | Y28: S | Z28: S | AA28: S | AG28: =SUM(M28:AF28) -> 210 | AH28: S | AI28: SA | AJ28: KY | AK28: KY | AL28: KY | AM28: KY | AN28: KY | AO28: KY | AP28: KY | AQ28: KY | AR28: KY | AS28: KY | AT28: KY | AU28: KY | AV28: KY | BB28: =SUM(M28:AF28,AH28:BA28) -> 210
B29: 20 | C29: EMİR KALKAN | K29: =SUM(E29:J29) -> 0 | M29: KY | N29: KY | O29: 45 | P29: 70 | Q29: SA | R29: S | S29: S | T29: S | U29: S | V29: S | W29: S | X29: S | Y29: S | Z29: S | AA29: S | AG29: =SUM(M29:AF29) -> 115 | AH29: S | AI29: KY | AJ29: KY | AK29: KY | AL29: KY | AM29: KY | AN29: KY | AO29: KY | AP29: KY | AQ29: KY | AR29: KY | AS29: KY | AT29: KY | AU29: KY | AV29: KY | BB29: =SUM(M29:AF29,AH29:BA29) -> 115
B30: 21 | C30: POYRAZ BAŞ | K30: =SUM(E30:J30) -> 0 | M30: KY | N30: KY | O30: KY | P30: KY | Q30: 45 | R30: 90 | S30: 90 | T30: 90 | U30: 90 | V30: 78 | W30: KY | X30: 80 | Y30: 45 | Z30: KY | AA30: KY | AG30: =SUM(M30:AF30) -> 608 | AH30: KY | AI30: KY | AJ30: KY | AK30: KY | AL30: KY | AM30: KY | AN30: KY | AO30: KY | AP30: KY | AQ30: KY | AR30: KY | AS30: KY | AT30: KY | AU30: KY | AV30: KY | BB30: =SUM(M30:AF30,AH30:BA30) -> 608
B31: 22 | C31: BERK DAVULCU | K31: =SUM(E31:J31) -> 0 | M31: 90 | N31: 90 | O31: 60 | P31: 45 | Q31: 45 | R31: 73 | S31: 59 | T31: 65 | U31: 70 | V31: SA | W31: 85 | X31: 90 | Y31: 90 | Z31: 90 | AA31: 90 | AG31: =SUM(M31:AF31) -> 1042 | AH31: 90 | AI31: 45 | AJ31: 45 | AK31: 75 | AL31: 45 | BB31: =SUM(M31:AF31,AH31:BA31) -> 1342
B32: 23 | C32: EYÜP SİLMEZ | K32: =SUM(E32:J32) -> 0 | M32: 90 | N32: 90 | O32: 87 | P32: 90 | Q32: 67 | R32: C | S32: C | T32: C | U32: 30 | V32: 90 | W32: 90 | X32: 90 | Y32: 90 | Z32: 45 | AA32: 90 | AG32: =SUM(M32:AF32) -> 949 | AH32: 70 | AI32: 90 | AJ32: 85 | AK32: 90 | AL32: 90 | AM32: 90 | BB32: =SUM(M32:AF32,AH32:BA32) -> 1464
B33: 24 | C33: ALP DEĞİRMENCİ | K33: =SUM(E33:J33) -> 0 | M33: 30 | N33: 30 | O33: 35 | P33: 45 | Q33: S | R33: S | S33: S | T33: S | U33: 20 | V33: 74 | W33: SA | X33: SA | Y33: 5 | Z33: 30 | AA33: 45 | AG33: =SUM(M33:AF33) -> 314 | AH33: SA | AI33: 45 | AJ33: 5 | AK33: SA | AL33: 25 | BB33: =SUM(M33:AF33,AH33:BA33) -> 389
B34: 25 | C34: HALİT YILDIRIM | K34: =SUM(E34:J34) -> 0 | M34: 45 | N34: SA | O34: KY | P34: KY | Q34: KY | R34: 17 | S34: 15 | T34: 90 | U34: 60 | V34: 90 | W34: 65 | X34: 40 | Y34: 45 | Z34: 72 | AA34: 65 | AG34: =SUM(M34:AF34) -> 604 | AH34: 20 | AI34: 25 | AJ34: SA | AK34: 20 | AL34: SA | AM34: SA | BB34: =SUM(M34:AF34,AH34:BA34) -> 669
B35: 26 | C35: EREN ALP KOÇAK | K35: =SUM(E35:J35) -> 0 | M35: KY | N35: KY | O35: KY | P35: KY | Q35: KY | R35: 45 | S35: 45 | T35: 25 | U35: S | V35: S | W35: S | X35: S | Y35: S | Z35: S | AA35: S | AG35: =SUM(M35:AF35) -> 115 | AH35: S | AI35: KY | AJ35: 45 | AK35: 75 | AL35: 45 | AM35: 45 | BB35: =SUM(M35:AF35,AH35:BA35) -> 325
B36: 27 | C36: ÖMER FARUK ÖZKANCA | K36: =SUM(E36:J36) -> 0 | M36: KY | N36: KY | O36: KY | P36: KY | Q36: KY | R36: KY | S36: KY | T36: 25 | U36: KY | V36: KY | W36: 6 | X36: SA | Y36: SA | Z36: 20 | AA36: 20 | AG36: =SUM(M36:AF36) -> 71 | AH36: 45 | AI36: 45 | AJ36: S | AK36: 45 | AL36: KY | BB36: =SUM(M36:AF36,AH36:BA36) -> 206
B37: 28 | C37: YİĞİT EFE TEPE | K37: =SUM(E37:J37) -> 0 | AA37: 25 | AG37: =SUM(M37:AF37) -> 25 | AH37: SA | AI37: KY | AJ37: SA | AK37: SA | AL37: SA | AM37: SA | BB37: =SUM(M37:AF37,AH37:BA37) -> 25
B38: 29 | C38: BATUHAN ÖNCEL | K38: =SUM(E38:J38) -> 0 | AG38: =SUM(M38:AF38) -> 0 | AH38: SA | AI38: 25 | AJ38: 65 | AK38: 32 | AL38: KY | AM38: SA | BB38: =SUM(M38:AF38,AH38:BA38) -> 122
B39: 30 | C39: KUZEY DURAK | K39: =SUM(E39:J39) -> 0 | AG39: =SUM(M39:AF39) -> 0 | AL39: 45 | BB39: =SUM(M39:AF39,AH39:BA39) -> 45
B40: MAÇ SONUCU | K40: =SUM(E40:J40) -> 0 | M40: 0 | N40: 1 | O40: 1 | P40: 1 | Q40: 1 | R40: 0 | S40: 1 | T40: 5 | U40: 0 | V40: 2 | W40: 0 | X40: 1 | Y40: 1 | Z40: 1 | AA40: 1 | AG40: 15 | AH40: 2 | AI40: 2 | AJ40: 2 | AK40: 0 | AL40: 1 | AM40: 1 | BA40: =SUM(AH40:AZ40) -> 8 | BB40: =SUM(M40:AE40)+SUM(AH40:AZ40) -> 24
K41: =SUM(E41:J41) -> 0 | M41: 3 | N41: 3 | O41: 1 | P41: 3 | Q41: 2 | R41: 1 | S41: 1 | T41: 3 | U41: 1 | V41: 1 | W41: 0 | X41: 0 | Y41: 1 | Z41: 0 | AA41: 1 | AG41: 20 | AH41: 0 | AI41: 4 | AJ41: 1 | AK41: 2 | AL41: 1 | AM41: 5 | BA41: =SUM(AH41:AZ41) -> 13 | BB41: =SUM(M41:AE41)+SUM(AH41:AZ41) -> 34
...

Sheet GOL
B2: GOL
B3: U-19 2025-2026 Sezonu
E4: HAZIRLIK MAÇI | L4: HAZIRLIK MAÇLARI | M4: 1. DEVRE | AF4: DEVRE ARASI | AG4: TOPLAM | AH4: 2. DEVRE
E5: 1 | F5: 2 | G5: 3 | H5: 4 | I5: 5 | J5: 6 | K5: T | M5: 1 | N5: 2 | O5: 3 | P5: 4 | Q5: 5 | R5: 6 | S5: 7 | T5: 8 | U5: 9 | V5: 10 | W5: 11 | X5: 12 | Y5: 13 | Z5: 14 | AA5: 15 | AH5: 16 | AI5: 17 | AJ5: 18 | AK5: 19 | AL5: 20 | AM5: 21 | AN5: 22 | AO5: 23 | AP5: 24 | AQ5: 25 | AR5: 26 | AS5: 27 | AT5: 28 | AU5: 29 | AV5: 30
E6: D | F6: E | G6: D | H6: E | I6: E | J6: D | M6: D | N6: E | O6: D | P6: E | Q6: D | R6: E | S6: D | T6: E | U6: D | V6: E | W6: D | X6: E | Y6: D | Z6: E | AA6: D | AH6: E | AI6: D | AJ6: E | AK6: D | AL6: E | AM6: D | AN6: E | AO6: D | AP6: E | AQ6: D | AR6: E | AS6: D | AT6: E | AU6: D | AV6: E
K7: TOPLAM | M7: SANCAKTEPE SPOR | N7: GÖLCÜKSPOR | O7: KESTEL ÇİLEK SPOR KULÜBÜ | P7: BULVARSPOR | Q7: KARTAL SPORTİF FAALİYETLERİ A.Ş. | R7: SULTANBEYLİ BELEDİYE SPOR | S7: DUDULLU | T7: İNKILAP FUTBOL SPOR KULÜBÜ | U7: GÜZİDE GEBZE SPOR KULÜBÜ | V7: PAŞABAHÇE | W7: KARACABEY BELEDİYE SPOR A.Ş. | X7: KULLAR 1975 SPOR | Y7: YALOVA FK 77 SPOR KULÜBÜ | Z7: MALTEPESPOR | AA7: BEYKOZ ANADOLU SPOR A.Ş. | AH7: SANCAKTEPE SPOR | AI7: GÖLCÜKSPOR | AJ7: KESTEL ÇİLEK SPOR KULÜBÜ | AK7: BULVARSPOR | AL7: KARTAL SPORTİF FAALİYETLERİ A.Ş. | AM7: SULTANBEYLİ BELEDİYE SPOR | AN7: DUDULLU | AO7: İNKILAP FUTBOL SPOR KULÜBÜ | AP7: GÜZİDE GEBZE SPOR KULÜBÜ | AQ7: PAŞABAHÇE | AR7: KARACABEY BELEDİYE SPOR A.Ş. | AS7: KULLAR 1975 SPOR | AT7: YALOVA FK 77 SPOR KULÜBÜ | AU7: MALTEPESPOR | AV7: BEYKOZ ANADOLU SPOR A.Ş. | BA7: SON
M8: 17 | N8: 24 | O8: 1 | P8: 8 | Q8: 15 | R8: 22 | S8: 29 | T8: 5 | U8: 12 | V8: 19 | W8: 26 | X8: 3 | Y8: 10 | Z8: 17 | AA8: 24 | AH8: 29 | AI8: 7 | AJ8: 14 | AK8: 21 | AL8: 28 | AM8: 4 | AN8: 11 | AO8: 18 | AP8: 25 | AQ8: 4 | AR8: 11 | AS8: 25 | AT8: 1 | AU8: 8 | AV8: 15 | AW8: =DAKIKA!AW8 | AX8: =DAKIKA!AX8 | AY8: =DAKIKA!AY8 | AZ8: =DAKIKA!AZ8
M9: EYLÜL | O9: EKİM | T9: KASIM | X9: ARALIK | AI9: OCAK | AM9: ŞUBAT | AQ9: MART | AT9: NİSAN
B10: 1 | C10: ÖMÜR ÇİLESİZ | K10: =SUM(E10:J10) -> 0 | AG10: =SUM(M10:AF10) -> 0 | BB10: =SUM(M10:AF10,AH10:BA10) -> 0
B11: 2 | C11: SİNAN SARGIN | K11: =SUM(E11:J11) -> 0 | AG11: =SUM(M11:AF11) -> 0 | BB11: =SUM(M11:AF11,AH11:BA11) -> 0
B12: 3 | C12: EMİRHAN ÇELİK | K12: =SUM(E12:J12) -> 0 | T12: 1 | AG12: =SUM(M12:AF12) -> 1 | AH12: SK | BB12: =SUM(M12:AF12,AH12:BA12) -> 1
B13: 4 | C13: YASİN ERDEM ÖZTÜRK | K13: =SUM(E13:J13) -> 0 | AG13: =SUM(M13:AF13) -> 0 | BB13: =SUM(M13:AF13,AH13:BA13) -> 0
B14: 5 | C14: YASİN ALBAYRAK | K14: =SUM(E14:J14) -> 0 | O14: SK | P14: SK | U14: SK | AG14: =SUM(M14:AF14) -> 0 | AJ14: SK | BB14: =SUM(M14:AF14,AH14:BA14) -> 0
B15: 6 | C15: ULAÇ KANDAZ | K15: =SUM(E15:J15) -> 0 | O15: SK | AG15: =SUM(M15:AF15) -> 0 | AJ15: SK | AK15: SK | AL15: SK | BB15: =SUM(M15:AF15,AH15:BA15) -> 0
B16: 7 | C16: METEHAN COŞKUN | K16: =SUM(E16:J16) -> 0 | P16: SK | S16: 1 | T16: SK | W16: SK | Y16: SK | AG16: =SUM(M16:AF16) -> 1 | AJ16: SK | BB16: =SUM(M16:AF16,AH16:BA16) -> 1
B17: 8 | C17: UMUT EGEMEN KUTLU | K17: =SUM(E17:J17) -> 0 | AG17: =SUM(M17:AF17) -> 0 | BB17: =SUM(M17:AF17,AH17:BA17) -> 0
B18: 9 | C18: MİRAÇ EMİR YILDIZ | K18: =SUM(E18:J18) -> 0 | M18: SK | AG18: =SUM(M18:AF18) -> 0 | BB18: =SUM(M18:AF18,AH18:BA18) -> 0
B19: 10 | C19: ARDA AYVALI | K19: =SUM(E19:J19) -> 0 | Z19: SK | AG19: =SUM(M19:AF19) -> 0 | BB19: =SUM(M19:AF19,AH19:BA19) -> 0
B20: 11 | C20: TÜRKER ÇEBİ | K20: =SUM(E20:J20) -> 0 | Q20: SK | X20: SK | AG20: =SUM(M20:AF20) -> 0 | AI20: SK | BB20: =SUM(M20:AF20,AH20:BA20) -> 0
B21: 12 | C21: EGE BARIŞ DEMİR | K21: =SUM(E21:J21) -> 0 | M21: SK | O21: SK | R21: SK | T21: SK | X21: SK | Y21: 1 | AG21: =SUM(M21:AF21) -> 1 | AH21: 1 | AJ21: SK | AL21: SK | AM21: SK | BB21: =SUM(M21:AF21,AH21:BA21) -> 2
B22: 13 | C22: ARDA ÇORUK | K22: =SUM(E22:J22) -> 0 | AG22: =SUM(M22:AF22) -> 0 | AK22: SK | BB22: =SUM(M22:AF22,AH22:BA22) -> 0
B23: 14 | C23: UMUT BAK | K23: =SUM(E23:J23) -> 0 | M23: SK | N23: SK | AG23: =SUM(M23:AF23) -> 0 | BB23: =SUM(M23:AF23,AH23:BA23) -> 0
B24: 15 | C24: BERKAY ÜST | K24: =SUM(E24:J24) -> 0 | AG24: =SUM(M24:AF24) -> 0 | BB24: =SUM(M24:AF24,AH24:BA24) -> 0
B25: 16 | C25: KADİR GEDİK | K25: =SUM(E25:J25) -> 0 | Q25: SK | W25: SK | X25: 1 | Z25: KK | AG25: =SUM(M25:AF25) -> 1 | AJ25: KK | BB25: =SUM(M25:AF25,AH25:BA25) -> 1
B26: 17 | C26: ALPEREN VAROL | K26: =SUM(E26:J26) -> 0 | T26: 1 | AG26: =SUM(M26:AF26) -> 1 | AH26: SK | BB26: =SUM(M26:AF26,AH26:BA26) -> 1
B27: 18 | C27: YİĞİT YAZICI | K27: =SUM(E27:J27) -> 0 | Z27: SK | AG27: =SUM(M27:AF27) -> 0 | BB27: =SUM(M27:AF27,AH27:BA27) -> 0
B28: 19 | C28: EMİR KAMA | K28: =SUM(E28:J28) -> 0 | AG28: =SUM(M28:AF28) -> 0 | BB28: =SUM(M28:AF28,AH28:BA28) -> 0
B29: 20 | C29: EMİR KALKAN | K29: =SUM(E29:J29) -> 0 | AG29: =SUM(M29:AF29) -> 0 | BB29: =SUM(M29:AF29,AH29:BA29) -> 0
B30: 21 | C30: POYRAZ BAŞ | K30: =SUM(E30:J30) -> 0 | AG30: =SUM(M30:AF30) -> 0 | BB30: =SUM(M30:AF30,AH30:BA30) -> 0
B31: 22 | C31: BERK DAVULCU | K31: =SUM(E31:J31) -> 0 | Q31: 1 | T31: 1 | Z31: SK | AA31: 1 | AG31: =SUM(M31:AF31) -> 3 | BB31: =SUM(M31:AF31,AH31:BA31) -> 3
B32: 23 | C32: EYÜP SİLMEZ | K32: =SUM(E32:J32) -> 0 | N32: 1 | O32: 1 | Q32: KK | V32: 1 | AG32: =SUM(M32:AF32) -> 3 | AI32: 2 | AJ32: 2 | AL32: 1 | AM32: 1 | BB32: =SUM(M32:AF32,AH32:BA32) -> 9
B33: 24 | C33: ALP DEĞİRMENCİ | K33: =SUM(E33:J33) -> 0 | P33: 1 | U33: SK | V33: SK | AG33: =SUM(M33:AF33) -> 1 | AJ33: SK | BB33: =SUM(M33:AF33,AH33:BA33) -> 1
B34: 25 | C34: HALİT YILDIRIM | K34: =SUM(E34:J34) -> 0 | T34: 2 | V34: 1 | W34: SK | Z34: 1 | AG34: =SUM(M34:AF34) -> 4 | BB34: =SUM(M34:AF34,AH34:BA34) -> 4
B35: 26 | C35: EREN ALP KOÇAK | K35: =SUM(E35:J35) -> 0 | AG35: =SUM(M35:AF35) -> 0 | BB35: =SUM(M35:AF35,AH35:BA35) -> 0
B36: 27 | C36: ÖMER FARUK ÖZKANCA | K36: =SUM(E36:J36) -> 0 | T36: KK | AG36: =SUM(M36:AF36) -> 0 | AH36: 1 | BB36: =SUM(M36:AF36,AH36:BA36) -> 1
B37: 28 | C37: YİĞİT EFE TEPE | K37: =SUM(E37:J37) -> 0 | AG37: =SUM(M37:AF37) -> 0 | BB37: =SUM(M37:AF37,AH37:BA37) -> 0
B38: 29 | C38: BATUHAN ÖNCEL | K38: =SUM(E38:J38) -> 0 | AG38: =SUM(M38:AF38) -> 0 | AK38: SK | BB38: =SUM(M38:AF38,AH38:BA38) -> 0
B39: 30 | C39: KUZEY DURAK | K39: =SUM(E39:J39) -> 0 | AG39: =SUM(M39:AF39) -> 0 | BB39: =SUM(M39:AF39,AH39:BA39) -> 0
B40: MAÇ SONUCU | K40: =SUM(E40:J40) -> 0 | M40: {=DAKIKA!M40:AE40} -> 0 | N40: 1 | O40: 1 | P40: 1 | Q40: 1 | R40: 0 | S40: 1 | T40: 5 | U40: 0 | V40: 2 | W40: 0 | X40: 1 | Y40: 1 | Z40: 1 | AA40: 1 | AG40: =SUM(M40:AF40) -> 16 | AH40: 2 | AI40: 2 | AJ40: 2 | AK40: 0 | AL40: 1 | AM40: 1 | BA40: =SUM(ANCHORARRAY(AH40)) -> #NAME? | BB40: =SUM(M40:AE40)+SUM(AH40:AZ40) -> 24
K41: =SUM(E41:J41) -> 0 | M41: =DAKIKA!M41 -> 3 | N41: =DAKIKA!N41 -> 3 | O41: 1 | P41: =DAKIKA!P41 -> 3 | Q41: 2 | R41: =DAKIKA!R41 -> 1 | S41: =DAKIKA!S41 -> 1 | T41: 3 | U41: 1 | V41: 1 | W41: 0 | X41: 0 | Y41: =DAKIKA!Y41 -> 1 | Z41: 0 | AA41: =DAKIKA!AA41 -> 1 | AC41: =DAKIKA!AC41 | AD41: =DAKIKA!AD41 | AE41: =DAKIKA!AE41 | AG41: =SUM(M41:AF41) -> 21 | AH41: 0 | AI41: 4 | AJ41: 1 | AK41: 2 | AL41: 1 | AM41: 5 | BA41: =SUM(ANCHORARRAY(AH41)) -> #NAME? | BB41: =SUM(M41:AE41)+SUM(AH41:AZ41) -> 34
...

Sheet ASİST
B2: ASİST
B3: U-19 2025-2026 Sezonu
E4: HAZIRLIK MAÇI | L4: HAZIRLIK MAÇLARI | M4: 1. DEVRE | AF4: DEVRE ARASI | AG4: TOPLAM | AH4: 2. DEVRE
E5: 1 | F5: 2 | G5: 3 | H5: 4 | I5: 5 | J5: 6 | K5: T | M5: 1 | N5: 2 | O5: 3 | P5: 4 | Q5: 5 | R5: 6 | S5: 7 | T5: 8 | U5: 9 | V5: 10 | W5: 11 | X5: 12 | Y5: 13 | Z5: 14 | AA5: 15 | AH5: 16 | AI5: 17 | AJ5: 18 | AK5: 19 | AL5: 20 | AM5: 21 | AN5: 22 | AO5: 23 | AP5: 24 | AQ5: 25 | AR5: 26 | AS5: 27 | AT5: 28 | AU5: 29 | AV5: 30
E6: D | F6: E | G6: D | H6: E | I6: E | J6: E | M6: D | N6: E | O6: D | P6: E | Q6: D | R6: E | S6: D | T6: E | U6: D | V6: E | W6: D | X6: E | Y6: D | Z6: E | AA6: D | AH6: E | AI6: D | AJ6: E | AK6: D | AL6: E | AM6: D | AN6: E | AO6: D | AP6: E | AQ6: D | AR6: E | AS6: D | AT6: E | AU6: D | AV6: E
K7: TOPLAM | M7: =DAKIKA!M7 -> SANCAKTEPE SPOR | N7: =DAKIKA!N7 -> GÖLCÜKSPOR | O7: =DAKIKA!O7 -> KESTEL ÇİLEK SPOR KULÜBÜ | P7: =DAKIKA!P7 -> BULVARSPOR | Q7: =DAKIKA!Q7 -> KARTAL SPORTİF FAALİYETLERİ A.Ş. | R7: =DAKIKA!R7 -> SULTANBEYLİ BELEDİYE SPOR | S7: =DAKIKA!S7 -> DUDULLU | T7: =DAKIKA!T7 -> İNKILAP FUTBOL SPOR KULÜBÜ | ... AA7: =DAKIKA!AA7 -> BEYKOZ ANADOLU SPOR A.Ş. | AH7: =DAKIKA!AH7 -> SANCAKTEPE SPOR | AI7: =DAKIKA!AI7 -> GÖLCÜKSPOR | AJ7: =DAKIKA!AJ7 -> KESTEL ÇİLEK SPOR KULÜBÜ | AK7: =DAKIKA!AK7 -> BULVARSPOR | AL7: =DAKIKA!AL7 -> KARTAL SPORTİF FAALİYETLERİ A.Ş. | AM7: =DAKIKA!AM7 -> SULTANBEYLİ BELEDİYE SPOR | AN7: =DAKIKA!AN7 -> DUDULLU | AO7: =DAKIKA!AO7 -> İNKILAP FUTBOL SPOR KULÜBÜ | ... AV7: =DAKIKA!AV7 -> BEYKOZ ANADOLU SPOR A.Ş. | BA7: SON
M8: {=DAKIKA!M8:BA8} -> 17 | N8: 24 | O8: 1 | P8: 8 | Q8: 15 | R8: 22 | S8: 29 | T8: 5 | U8: 12 | V8: 19 | W8: 26 | X8: 3 | Y8: 10 | Z8: 17 | AA8: 24 | AH8: 29 | AI8: 7 | AJ8: 14 | AK8: 21 | AL8: 28 | AM8: 4 | AN8: 11 | AO8: 18 | AP8: 25 | AQ8: 4 | AR8: 11 | AS8: 25 | AT8: 1 | AU8: 8 | AV8: 15
M9: EYLÜL | O9: EKİM | T9: KASIM | X9: ARALIK | AI9: OCAK | AM9: ŞUBAT | AQ9: MART | AT9: NİSAN
B10: 1 | C10: ÖMÜR ÇİLESİZ | K10: =SUM(E10:J10) -> 0 | AG10: =SUM(M10:AF10) -> 0 | BB10: =SUM(M10:AF10,AH10:BA10) -> 0
B11: 2 | C11: SİNAN SARGIN | K11: =SUM(E11:J11) -> 0 | AG11: =SUM(M11:AF11) -> 0 | BB11: =SUM(M11:AF11,AH11:BA11) -> 0
B12: 3 | C12: EMİRHAN ÇELİK | K12: =SUM(E12:J12) -> 0 | AG12: =SUM(M12:AF12) -> 0 | BB12: =SUM(M12:AF12,AH12:BA12) -> 0
B13: 4 | C13: YASİN ERDEM ÖZTÜRK | K13: =SUM(E13:J13) -> 0 | AG13: =SUM(M13:AF13) -> 0 | BB13: =SUM(M13:AF13,AH13:BA13) -> 0
B14: 5 | C14: YASİN ALBAYRAK | K14: =SUM(E14:J14) -> 0 | AG14: =SUM(M14:AF14) -> 0 | BB14: =SUM(M14:AF14,AH14:BA14) -> 0
B15: 6 | C15: ULAÇ KANDAZ | K15: =SUM(E15:J15) -> 0 | AG15: =SUM(M15:AF15) -> 0 | BB15: =SUM(M15:AF15,AH15:BA15) -> 0
B16: 7 | C16: METEHAN COŞKUN | K16: =SUM(E16:J16) -> 0 | AG16: =SUM(M16:AF16) -> 0 | BB16: =SUM(M16:AF16,AH16:BA16) -> 0
B17: 8 | C17: UMUT EGEMEN KUTLU | K17: =SUM(E17:J17) -> 0 | AG17: =SUM(M17:AF17) -> 0 | BB17: =SUM(M17:AF17,AH17:BA17) -> 0
B18: 9 | C18: MİRAÇ EMİR YILDIZ | K18: =SUM(E18:J18) -> 0 | AG18: =SUM(M18:AF18) -> 0 | BB18: =SUM(M18:AF18,AH18:BA18) -> 0
B19: 10 | C19: ARDA AYVALI | K19: =SUM(E19:J19) -> 0 | O19: 1 | AG19: =SUM(M19:AF19) -> 1 | BB19: =SUM(M19:AF19,AH19:BA19) -> 1
B20: 11 | C20: TÜRKER ÇEBİ | K20: =SUM(E20:J20) -> 0 | AG20: =SUM(M20:AF20) -> 0 | BB20: =SUM(M20:AF20,AH20:BA20) -> 0
B21: 12 | C21: EGE BARIŞ DEMİR | K21: 0 | AG21: 0 | AJ21: 1 | BB21: 0
B22: 13 | C22: ARDA ÇORUK | K22: =SUM(E22:J22) -> 0 | AG22: =SUM(M22:AF22) -> 0 | BB22: =SUM(M22:AF22,AH22:BA22) -> 0
B23: 14 | C23: UMUT BAK | K23: =SUM(E23:J23) -> 0 | AG23: =SUM(M23:AF23) -> 0 | BB23: =SUM(M23:AF23,AH23:BA23) -> 0
B24: 15 | C24: BERKAY ÜST | K24: =SUM(E24:J24) -> 0 | T24: 1 | AG24: =SUM(M24:AF24) -> 1 | BB24: =SUM(M24:AF24,AH24:BA24) -> 1
B25: 16 | C25: KADİR GEDİK | K25: =SUM(E25:J25) -> 0 | N25: 1 | Q25: 1 | V25: 1 | AG25: =SUM(M25:AF25) -> 3 | BB25: =SUM(M25:AF25,AH25:BA25) -> 3
B26: 17 | C26: ALPEREN VAROL | K26: =SUM(E26:J26) -> 0 | T26: 2 | AG26: =SUM(M26:AF26) -> 2 | AH26: 2 | AI26: 2 | BB26: =SUM(M26:AF26,AH26:BA26) -> 6
B27: 18 | C27: YİĞİT YAZICI | K27: =SUM(E27:J27) -> 0 | AG27: =SUM(M27:AF27) -> 0 | BB27: =SUM(M27:AF27,AH27:BA27) -> 0
B28: 19 | C28: EMİR KAMA | K28: =SUM(E28:J28) -> 0 | AG28: =SUM(M28:AF28) -> 0 | BB28: =SUM(M28:AF28,AH28:BA28) -> 0
B29: 20 | C29: EMİR KALKAN | K29: =SUM(E29:J29) -> 0 | AG29: =SUM(M29:AF29) -> 0 | BB29: =SUM(M29:AF29,AH29:BA29) -> 0
B30: 21 | C30: POYRAZ BAŞ | K30: =SUM(E30:J30) -> 0 | AG30: =SUM(M30:AF30) -> 0 | BB30: =SUM(M30:AF30,AH30:BA30) -> 0
B31: 22 | C31: BERK DAVULCU | K31: =SUM(E31:J31) -> 0 | AG31: =SUM(M31:AF31) -> 0 | BB31: =SUM(M31:AF31,AH31:BA31) -> 0
B32: 23 | C32: EYÜP SİLMEZ | K32: =SUM(E32:J32) -> 0 | X32: 1 | AG32: =SUM(M32:AF32) -> 1 | BB32: =SUM(M32:AF32,AH32:BA32) -> 1
B33: 24 | C33: ALP DEĞİRMENCİ | K33: =SUM(E33:J33) -> 0 | AG33: =SUM(M33:AF33) -> 0 | BB33: =SUM(M33:AF33,AH33:BA33) -> 0
B34: 25 | C34: HALİT YILDIRIM | K34: =SUM(E34:J34) -> 0 | T34: 1 | AG34: =SUM(M34:AF34) -> 1 | BB34: =SUM(M34:AF34,AH34:BA34) -> 1
B35: 26 | C35: EREN ALP KOÇAK | K35: =SUM(E35:J35) -> 0 | T35: 1 | AG35: =SUM(M35:AF35) -> 1 | BB35: =SUM(M35:AF35,AH35:BA35) -> 1
B36: 27 | C36: ÖMER FARUK ÖZKANCA | K36: =SUM(E36:J36) -> 0 | Z36: 1 | AG36: =SUM(M36:AF36) -> 1 | BB36: =SUM(M36:AF36,AH36:BA36) -> 1
B37: 28 | C37: YİĞİT EFE TEPE | K37: =SUM(E37:J37) -> 0 | AG37: =SUM(M37:AF37) -> 0 | BB37: =SUM(M37:AF37,AH37:BA37) -> 0
B38: 29 | C38: BATUHAN ÖNCEL | K38: =SUM(E38:J38) -> 0 | AG38: =SUM(M38:AF38) -> 0 | BB38: =SUM(M38:AF38,AH38:BA38) -> 0
B39: 30 | C39: KUZEY DURAK | K39: =SUM(E39:J39) -> 0 | AG39: =SUM(M39:AF39) -> 0 | BB39: =SUM(M39:AF39,AH39:BA39) -> 0
B40: MAÇ SONUCU | K40: =SUM(E40:J40) -> 0 | M40: 0 | N40: 1 | O40: 1 | P40: 1 | Q40: 1 | R40: 0 | S40: 1 | T40: 5 | U40: 0 | V40: 2 | W40: 0 | X40: 1 | Y40: 1 | Z40: 1 | AA40: 1 | AG40: =SUM(M40:AF40) -> 16 | AH40: 2 | AI40: 2 | AJ40: 2 | AK40: 0 | AL40: 1 | AM40: 1 | BA40: =SUM(ANCHORARRAY(AH40)) -> #NAME? | BB40: =SUM(M40:AE40)+SUM(AH40:AZ40) -> 24
K41: =SUM(E41:J41) -> 0 | M41: 3 | N41: 3 | O41: 1 | P41: 3 | Q41: 2 | R41: 1 | S41: 1 | T41: 3 | U41: 1 | V41: 1 | W41: 0 | X41: 0 | Y41: 1 | Z41: 0 | AA41: 1 | AG41: =SUM(M41:AF41) -> 21 | AH41: 0 | AI41: 4 | AJ41: 1 | AK41: 2 | AL41: 1 | AM41: 5 | BA41: =SUM(ANCHORARRAY(AH41)) -> #NAME? | BB41: =SUM(M41:AE41)+SUM(AH41:AZ41) -> 34
...

Sheet KART
B2: KART
B5: KADIN FUTBOL A TAKIM 2022 - 2023 Sezonu
H6: 1. DEVRE | R6: DEVRE ARASI | S6: DEVRE ARASI | T6: 2. DEVRE | AD6: PLAY OFF
H7: 1 | I7: 2 | J7: 3 | K7: 4 | M7: 5 | N7: 6 | O7: 7 | P7: 8 | Q7: 9 | T7: 10 | U7: 11 | V7: 12 | W7: 13 | X7: 14 | Y7: 15 | Z7: 16 | AB7: 17 | AC7: 18 | AD7: 19 | AE7: 20 | AF7: 21 | AG7: 22 | AH7: 23
H8: D | I8: E | J8: D | K8: E | M8: D | N8: E | O8: E | P8: D | Q8: E | T8: E | U8: D | V8: E | W8: D | X8: E | Y8: D | Z8: D | AB8: E | AC8: D | AD8: E | AE8: D | AF8: E | AG8: D | AH8: T
AH9: FINAL
H12: EYLÜL | K12: EKİM | O12: KASIM | T12: ARALIK | X12: OCAK | AB12: ŞUBAT | AF12: MART
B13: 1 | C13: ALİ EYMEN AYDIN | E13: SARI | F13: =SUM(H13:K13,M13:Q13,T13:Z13,AB13:AH13) -> 0 | L13: MİLLİ MAÇ | R13: DEVRE ARASI | S13: DEVRE ARASI | AA13: MİLLİ MAÇ
E14: KIRMIZI | F14: =SUM(H14:K14,M14:Q14,T14:Z14,AB14:AH14) -> 0
B15: 2 | C15: POYRAZ DUMAN | E15: SARI | F15: =SUM(H15:K15,M15:Q15,T15:Z15,AB15:AH15) -> 0
E16: KIRMIZI | F16: =SUM(H16:K16,M16:Q16,T16:Z16,AB16:AH16) -> 0
B17: 3 | C17: ALİ SERTAN AÇAR | E17: SARI | F17: =SUM(H17:K17,M17:Q17,T17:Z17,AB17:AH17) -> 0
E18: KIRMIZI | F18: =SUM(H18:K18,M18:Q18,T18:Z18,AB18:AH18) -> 0
B19: 4 | C19: KARTAL MERT EFE | E19: SARI | F19: =SUM(H19:K19,M19:Q19,T19:Z19,AB19:AH19) -> 1 | N19: 1
E20: KIRMIZI | F20: =SUM(H20:K20,M20:Q20,T20:Z20,AB20:AH20) -> 0
B21: 5 | C21: SARP ÖZKÖK | E21: SARI | F21: =SUM(H21:K21,M21:Q21,T21:Z21,AB21:AH21) -> 1 | W21: 1
E22: KIRMIZI | F22: =SUM(H22:K22,M22:Q22,T22:Z22,AB22:AH22) -> 0
B23: 6 | C23: UFUK ÇELİKTEN | E23: SARI | F23: =SUM(H23:K23,M23:Q23,T23:Z23,AB23:AH23) -> 0
E24: KIRMIZI | F24: =SUM(H24:K24,M24:Q24,T24:Z24,AB24:AH24) -> 0
B25: 7 | C25: NAZLICAN PARLAK | E25: SARI | F25: =SUM(H25:K25,M25:Q25,T25:Z25,AB25:AH25) -> 1 | M25: 1
E26: KIRMIZI | F26: =SUM(H26:K26,M26:Q26,T26:Z26,AB26:AH26) -> 0
B27: 8 | C27: SEVİNÇ ÇORLU | E27: SARI | F27: =SUM(H27:K27,M27:Q27,T27:Z27,AB27:AH27) -> 0
E28: KIRMIZI | F28: =SUM(H28:K28,M28:Q28,T28:Z28,AB28:AH28) -> 0
B29: 9 | C29: YAŞAM GÖKSU | E29: SARI | F29: =SUM(H29:K29,M29:Q29,T29:Z29,AB29:AH29) -> 1 | AE29: 1
E30: KIRMIZI | F30: =SUM(H30:K30,M30:Q30,T30:Z30,AB30:AH30) -> 0
B31: 10 | C31: ZOTE NINA KPAHO | E31: SARI | F31: =SUM(H31:K31,M31:Q31,T31:Z31,AB31:AH31) -> 1 | P31: 1
E32: KIRMIZI | F32: =SUM(H32:K32,M32:Q32,T32:Z32,AB32:AH32) -> 0
B33: 11 | C33: ALTUN SANCAR | E33: SARI | F33: =SUM(H33:K33,M33:Q33,T33:Z33,AB33:AH33) -> 0
E34: KIRMIZI | F34: =SUM(H34:K34,M34:Q34,T34:Z34,AB34:AH34) -> 0
B35: 12 | C35: BUSEM ŞEKER | E35: SARI | F35: =SUM(H35:K35,M35:Q35,T35:Z35,AB35:AH35) -> 1 | I35: 1
E36: KIRMIZI | F36: =SUM(H36:K36,M36:Q36,T36:Z36,AB36:AH36) -> 1 | Z36: 1 | AB36: C | AC36: C | AD36: C
B37: 13 | C37: CANSU GÜREL | E37: SARI | F37: =SUM(H37:K37,M37:Q37,T37:Z37,AB37:AH37) -> 0
E38: KIRMIZI | F38: =SUM(H38:K38,M38:Q38,T38:Z38,AB38:AH38) -> 0
B39: 14 | C39: ECEM CUMERT | E39: SARI | F39: =SUM(H39:K39,M39:Q39,T39:Z39,AB39:AH39) -> 5 | K39: 1 | O39: 1 | Y39: 1 | AB39: 1 | AC39: C | AD39: 1
E40: KIRMIZI | F40: =SUM(H40:K40,M40:Q40,T40:Z40,AB40:AH40) -> 0
B41: 15 | C41: FATMA KARA ŞAHİNBAŞ | E41: SARI | F41: =SUM(H41:K41,M41:Q41,T41:Z41,AB41:AH41) -> 1 | AE41: 1
E42: KIRMIZI | F42: =SUM(H42:K42,M42:Q42,T42:Z42,AB42:AH42) -> 0
B43: 16 | C43: KRISTEN LEIGH RICKS | E43: SARI | F43: =SUM(H43:K43,M43:Q43,T43:Z43,AB43:AH43) -> 0
E44: KIRMIZI | F44: =SUM(H44:K44,M44:Q44,T44:Z44,AB44:AH44) -> 0
B45: 17 | C45: MERYEM CENNET ÇAL | E45: SARI | F45: =SUM(H45:K45,M45:Q45,T45:Z45,AB45:AH45) -> 4 | I45: 1 | V45: 1 | AB45: 1 | AG45: 1
...
